<mujoco model="ur5_robot">
    <actuator>
        <!-- Physical limits of the actuator. -->
        <!-- Values taken from https://www.universal-robots.com/articles/ur-articles/max-joint-torques/ -->
        <motor ctrllimited="true" ctrlrange="-150.0 150.0" joint="ur5_joint1" name="torq_j1"/>
        <motor ctrllimited="true" ctrlrange="-150.0 150.0" joint="ur5_joint2" name="torq_j2"/>
        <motor ctrllimited="true" ctrlrange="-150.0 150.0" joint="ur5_joint3" name="torq_j3"/>
        <motor ctrllimited="true" ctrlrange="-28.0 28.0" joint="ur5_joint4" name="torq_j4"/>
        <motor ctrllimited="true" ctrlrange="-28.0 28.0" joint="ur5_joint5" name="torq_j5"/>
        <motor ctrllimited="true" ctrlrange="-28.0 28.0" joint="ur5_joint6" name="torq_j6"/>
    </actuator>
    <asset>
        <material name="UR5Black" specular="0.5" shininess="0.25" rgba="0.033 0.033 0.033 1"/>
        <material name="UR5JointGray" specular="0.5" shininess="0.25" rgba="0.278 0.278 0.278 1"/>
        <material name="UR5LinkGray" specular="0.5" shininess="0.25" rgba="0.82 0.82 0.82 1"/>
        <material name="UR5CapBlue" specular="0.5" shininess="0.25" rgba="0.49 0.678 0.8 1"/>

        <mesh name="ur5_base_0" file="meshes/ur5_base_0.stl"/>
        <mesh name="ur5_base_1" file="meshes/ur5_base_1.stl"/>

        <mesh name="ur5_shoulder_0" file="meshes/ur5_shoulder_0.stl"/>
        <mesh name="ur5_shoulder_1" file="meshes/ur5_shoulder_1.stl"/>
        <mesh name="ur5_shoulder_2" file="meshes/ur5_shoulder_2.stl"/>

        <mesh name="ur5_upperarm_0" file="meshes/ur5_upperarm_0.stl"/>
        <mesh name="ur5_upperarm_1" file="meshes/ur5_upperarm_1.stl"/>
        <mesh name="ur5_upperarm_2" file="meshes/ur5_upperarm_2.stl"/>
        <mesh name="ur5_upperarm_3" file="meshes/ur5_upperarm_3.stl"/>

        <mesh name="ur5_forearm_0" file="meshes/ur5_forearm_0.stl"/>
        <mesh name="ur5_forearm_1" file="meshes/ur5_forearm_1.stl"/>
        <mesh name="ur5_forearm_2" file="meshes/ur5_forearm_2.stl"/>
        <mesh name="ur5_forearm_3" file="meshes/ur5_forearm_3.stl"/>

        <mesh name="ur5_wrist1_0" file="meshes/ur5_wrist1_0.stl"/>
        <mesh name="ur5_wrist1_1" file="meshes/ur5_wrist1_1.stl"/>
        <mesh name="ur5_wrist1_2" file="meshes/ur5_wrist1_2.stl"/>

        <mesh name="ur5_wrist2_0" file="meshes/ur5_wrist2_0.stl"/>
        <mesh name="ur5_wrist2_1" file="meshes/ur5_wrist2_1.stl"/>
        <mesh name="ur5_wrist2_2" file="meshes/ur5_wrist2_2.stl"/>
        <mesh name="ur5_wrist3" file="meshes/ur5_wrist3.stl"/>
    </asset>

    <worldbody>
        <body name="ur5_base" quat="0.707 0 0 -0.707">
            <!-- robot view -->
            <camera mode="fixed" name="robotview" pos="1.0 0 0.4" quat="0.653 0.271 0.271 0.653"/>
            <inertial diaginertia="0 0 0" mass="0" pos="0 0 0"/>
            <!-- mount attached here -->
            <geom mesh="ur5_base_0" material="UR5Black" type="mesh" contype="0" conaffinity="0" group="1"/>
            <geom mesh="ur5_base_1" material="UR5JointGray" type="mesh" contype="0" conaffinity="0" group="1"/>
            <geom type="capsule" size="0.06 0.03" pos="0 0 0.06"/>
            <body name="shoulder_link" pos="0 0 0.09159" quat="0 0 0 1">
                <inertial pos="0 0 0" mass="3.7" diaginertia="0.0149724 0.0149724 0.0104063"/>
                <joint name="ur5_joint1" limited="true" range="-6.28319 6.28319" damping="0.001" frictionloss="0.01"/>
                <geom quat="0 0 0 1" mesh="ur5_shoulder_0" material="UR5CapBlue" type="mesh" contype="0" conaffinity="0" group="1"/>
                <geom quat="0 0 0 1" mesh="ur5_shoulder_1" material="UR5JointGray" type="mesh" contype="0" conaffinity="0" group="1"/>
                <geom quat="0 0 0 1" mesh="ur5_shoulder_2" material="UR5Black" type="mesh" contype="0" conaffinity="0" group="1"/>
                <geom type="capsule" quat="0.707 0.707 0 0" size="0.06 0.06" pos="0 -0.09 0"/>
                <body name="upper_arm_link" pos="0 0.003 0" quat="0.707107 0.707107 0 0">
                    <inertial pos="-0.2125 0 0.136" quat="0.707107 0 0.707107 0" mass="8.393"
                              diaginertia="0.133886 0.133886 0.0151074"/>
                    <joint name="ur5_joint2" limited="true" range="-6.28319 6.28319" damping="0.001" frictionloss="0.01"/>
                    <geom pos="0 0 0.13585" quat="0.5 0.5 -0.5 -0.5" mesh="ur5_upperarm_0" material="UR5Black"
                          type="mesh" contype="0" conaffinity="0" group="1"/>
                    <geom pos="0 0 0.13585" quat="0.5 0.5 -0.5 -0.5" mesh="ur5_upperarm_1" material="UR5JointGray"
                          type="mesh" contype="0" conaffinity="0" group="1"/>
                    <geom pos="0 0 0.13585" quat="0.5 0.5 -0.5 -0.5" mesh="ur5_upperarm_2" material="UR5CapBlue"
                          type="mesh" contype="0" conaffinity="0" group="1"/>
                    <geom pos="0 0 0.13585" quat="0.5 0.5 -0.5 -0.5" mesh="ur5_upperarm_3" material="UR5LinkGray"
                          type="mesh" contype="0" conaffinity="0" group="1"/>
                    <geom type="capsule" pos="-0.2 0 0.13585" quat="0.5 0.5 -0.5 -0.5" size="0.06 0.2"/>
                    <body name="forearm_link" pos="-0.425 0 0">
                        <inertial pos="-0.196125 0 0.0165" quat="0.707107 0 0.707107 0" mass="2.275"
                                  diaginertia="0.0312168 0.0312168 0.004095"/>
                        <joint name="ur5_joint3" limited="true" range="-6.28319 6.28319" damping="0.001" frictionloss="0.01"/>
                        <geom pos="0 0 0.0165" quat="0.5 0.5 -0.5 -0.5" mesh="ur5_forearm_0" material="UR5Black"
                              type="mesh" contype="0" conaffinity="0" group="1"/>
                        <geom pos="0 0 0.0165" quat="0.5 0.5 -0.5 -0.5" mesh="ur5_forearm_1" material="UR5CapBlue"
                              type="mesh" contype="0" conaffinity="0" group="1"/>
                        <geom pos="0 0 0.0165" quat="0.5 0.5 -0.5 -0.5" mesh="ur5_forearm_2" material="UR5JointGray"
                              type="mesh" contype="0" conaffinity="0" group="1"/>
                        <geom pos="0 0 0.0165" quat="0.5 0.5 -0.5 -0.5" mesh="ur5_forearm_3" material="UR5LinkGray"
                              type="mesh" contype="0" conaffinity="0" group="1"/>
                        <geom type="capsule" pos="-0.2 0 0.0165" quat="0.5 0.5 -0.5 -0.5" size="0.04 0.2"/>
                        <body name="wrist_1_link" pos="-0.39225 0 0.10915">
                            <inertial pos="0 0 0" quat="0.5 0.5 -0.5 0.5" mass="1.219"
                                      diaginertia="0.0021942 0.00201389 0.00201389"/>
                            <joint name="ur5_joint4" limited="true" range="-6.28319 6.28319" damping="0.001" frictionloss="0.01"/>
                            <geom pos="0 0 -0.093" quat="0.707107 0.707107 0 0" mesh="ur5_wrist1_0"
                                  material="UR5CapBlue" type="mesh" contype="0" conaffinity="0" group="1"/>
                            <geom pos="0 0 -0.093" quat="0.707107 0.707107 0 0" mesh="ur5_wrist1_1"
                                  material="UR5JointGray" type="mesh" contype="0" conaffinity="0" group="1"/>
                            <geom pos="0 0 -0.093" quat="0.707107 0.707107 0 0" mesh="ur5_wrist1_2"
                                  material="UR5Black" type="mesh" contype="0" conaffinity="0" group="1"/>
                            <geom type="capsule" pos="0 0 -0.08" size="0.04 0.025"/>
                            <body name="wrist_2_link" pos="0 -0.09465 -1.9413e-11" quat="0.707107 0.707107 0 0">
                                <inertial pos="0 0 0" quat="0.5 0.5 -0.5 0.5" mass="1.219"
                                          diaginertia="0.0021942 0.00183104 0.00183104"/>
                                <joint name="ur5_joint5" limited="true" range="-6.28319 6.28319" damping="0.001" frictionloss="0.01"/>
                                <geom pos="0 0 -0.095" mesh="ur5_wrist2_0" material="UR5Black" type="mesh" contype="0" conaffinity="0" group="1"/>
                                <geom pos="0 0 -0.095" mesh="ur5_wrist2_1" material="UR5CapBlue" type="mesh" contype="0" conaffinity="0" group="1"/>
                                <geom pos="0 0 -0.095" mesh="ur5_wrist2_2" material="UR5JointGray" type="mesh" contype="0" conaffinity="0" group="1"/>
                                <geom type="capsule" pos="0 0 -0.09" size="0.04 0.025"/>
                                <body name="wrist_3_link" pos="0 0.0823 -1.688e-11" quat="0.707107 -0.707107 0 0">
                                    <inertial pos="2.41791e-06 6.11278e-05 0.0220526"
                                              quat="1 -0.000770182 0.000170278 -0.000438404" mass="0.386936"
                                              diaginertia="0.000802069 0.000759517 0.000188105"/>
                                    <joint name="ur5_joint6" limited="true" range="-6.28319 6.28319" damping="0.001" frictionloss="0.01"/>
                                    <geom pos="0 0 -0.0818" quat="0.707107 0.707107 0 0" material="UR5LinkGray"
                                          mesh="ur5_wrist3" type="mesh" contype="0" conaffinity="0" group="1"/>
                                    <geom type="capsule" pos="0 0 -0.0818" size="0.04 0.025"/>
                                    <body name="right_hand" pos="0 0 0" quat="0.707 0 0 0.707">
                                        <!-- This camera points out from the eef. -->
                                        <camera mode="fixed" name="eye_in_hand" pos="0.05 0 0"  fovy="75"/>
                                        <!-- To add gripper -->
                                    </body>
                                </body>
                            </body>
                        </body>
                    </body>
                </body>
            </body>
        </body>
    </worldbody>
</mujoco>
